<mujoco>
    <option>
        <flag gravity = "disable"/>
    </option>
    <worldbody>
        <body name = "link_1">
            <joint type = "hinge" axis = "0 1 0" name = "ground_joint"/>
            <geom type = "capsule" fromto = "0 0 0 0 0 0.5" name = "leg" size = ".03" mass = "1"/>
            <body name = "stick_2" pos = "0 0 .5">
                <joint type = "hinge" axis = "0 1 0" name = "middle_joint" pos = "0 0 0"/>
                <geom type = "capsule" size = ".01" fromto = "0 0 0 0 0 1"  mass = "5"/>
                <site name = "stick_end" pos = "0 0 1"/>
            </body>
                
                
        </body>
    </worldbody>
</mujoco>