<mujoco>
    <compiler angle = "degree"/>
    <option timestep = "0.001"/>
    <option>
        <flag gravity = "enable"/>
    
    </option>
    <worldbody>
        <!-- <geom name="floor" type="plane" pos="0 0 0" size="2 2 .1" rgba = "1 1 1 1" mass = "0"/> -->
        <body name = "propeller_base" pos = "0 0 0" gravcomp = "3">
            <joint type = "free" name = "free_joint"/>
            <geom type = "capsule" size = ".01 .1" axisangle = "0 1 0 90" mass = "1"/>
            <body name = "propeller_1" pos = ".1 0 0" >
                <geom name = "propeller_1_stick" type = "cylinder" size = ".01 .025" rgba = "0 1 0 1" mass = "0"/>
                <site name = "propeller_1_fan" type = "box" size = ".03 .01 .001" pos = "0 0 .022" rgba = "0 1 0 1" />
            </body>
            <body name = "propeller_2" pos = "-.1 0 0" >
                <geom name = "propeller_2_stick" type = "cylinder" size = ".01 .025" rgba = "0 0 1 1" mass = "0"/>
                <site name = "propeller_2_fan" type = "box" size = ".03 .01 .001" pos = "0 0 .022" rgba = "0 0 1 1" />
            </body>
            <body name = "leg">
                <joint type = "hinge" axis = "0 1 0" name = "prop_base_joint" pos = "0 0 0"/>
                
                <geom type = "box" fromto = "0 0 0 0 0 -.5" name = "leg" size = ".01 .01" mass = "1"/>
                <body name = "leg_2" pos = "0 0 -.5">
                    <joint type = "hinge" name = "knee" axis = "0 1 0"/>
                    <geom name = "leg_2_stick" type = "capsule" fromto = "0 0 0 0 0 -.4" size = ".01" mass = "1"/>
                    <site name = "foot" pos = "0 0 -.4"/>

                </body>
                <!-- <body name = "foot" pos = "0 0 -.5" >
                    <geom type = "box" size = "0.1 0.05 0.01" mass = "0"/>
                    <joint type = "hinge" axis = "0 1 0" name = "foot_joint"/>
                </body> -->
                
            </body>
        </body>
        
        
    </worldbody>
</mujoco>