<mujoco>
    <option>
        <flag gravity = "enable"/>
    </option>
    <worldbody>
        <body name = "link_1" quat = "1 0 0 0">
            <joint type = "ball"  name = "ground_joint"/>
            <geom type = "capsule" fromto = "0 0 0 0 0 0.5" name = "leg" size = ".02" mass = "1"/>
            <body name = "stick_2" pos = "0 0 .5">
                <joint type = "hinge" axis = "0 1 0" name = "middle_joint" pos = "0 0 0"/>
                <geom type = "capsule" size = ".02" fromto = "0 0 0 0 0 .5"  mass = "1"/>
                <!-- <geom type = "capsule" size = ".02" fromto = "0 0 0 0 0 .5"  mass = "0.001"/> -->
                <site name = "stick_end" pos = "0 0 .5"/>
                <body name = "prop_base" pos = "0 0 .5" >
                    <joint type = "ball" name = "prop_base_joint"/>
                    <geom name = "base_stick" type = "capsule" fromto = "-.1 0 0 .1 0 0" size = ".02" mass = "1"/>
                    <!-- <geom name = "base_stick" type = "capsule" fromto = "-.1 0 0 .1 0 0" size = ".02" mass = "0.001"/> -->
                    <body name = "propeller_1" pos = ".1 0 0">
                        <geom name = "propeller_1_stick" type = "cylinder" size = ".01 .025" rgba = "0 1 0 1" mass = "0"/>
                        <site name = "propeller_1_fan" type = "box" size = ".03 .01 .001" pos = "0 0 .022" rgba = "0 1 0 1" />
                    </body>
                    <body name = "propeller_2" pos = "-.1 0 0">
                        <geom name = "propeller_2_stick" type = "cylinder" size = ".01 .025" rgba = "0 0 1 1" mass = "0"/>
                        <site name = "propeller_2_fan" type = "box" size = ".03 .01 .001" pos = "0 0 .022" rgba = "0 0 1 1" />
                    </body>
                </body>
            </body>
                
                
        </body>
    </worldbody>
</mujoco>